// Copyright (c) 2017, the Dart project authors.  Please see the AUTHORS file
// for details. All rights reserved. Use of this source code is governed by a
// BSD-style license that can be found in the LICENSE file.

import 'package:observatory/service_io.dart';
import 'package:observatory/models.dart' as M;
import 'package:test/test.dart';
import 'test_helper.dart';
import 'service_test_common.dart';

// AUTOGENERATED START
//
// Update these constants by running:
//
//     dart runtime/observatory/tests/service/test_helper.dart update-lines
//
const int LINE_A = 41;
// AUTOGENERATED END

class Foo {}

doThrow() {
  throw "TheException";
  return "end of doThrow";
}

asyncThrower() async {
  await 0; // force async gap
  doThrow();
}

testeeMain() async {
  try {
    // caught.
    try {
      await asyncThrower();
    } catch (e) {}

    // uncaught.
    try {
      await asyncThrower(); // LINE_A.
    } on double catch (e) {}
  } on Foo catch (e) {}
}

var tests = <IsolateTest>[
  hasStoppedWithUnhandledException,
  (Isolate isolate) async {
    print("We stopped!");
    var stack = await isolate.getStack();
    expect(stack['asyncCausalFrames'], isNotNull);
    var asyncStack = stack['asyncCausalFrames'];
    expect(asyncStack.length, greaterThanOrEqualTo(2));
    expect(asyncStack[0].toString(), contains('doThrow'));
    expect(asyncStack[1].toString(), contains('asyncThrower'));
    // There was no await'er for "doThrow()".
  }
];

main(args) => runIsolateTests(args, tests,
    pause_on_unhandled_exceptions: true,
    testeeConcurrent: testeeMain,
    extraArgs: extraDebuggingArgs);
